<?xml version="1.0"?>
<robot name="cart"
xmlns:xacro="http://www.ros.org/wiki/xacro">
	
	<material name="red">
		<color rgba="1 0 0 1"/>
	</material>
	
	<material name="green">
		<color rgba="0 1 0 1"/>
	</material>
	
	<material name="blue">
		<color rgba="0 0 1 1"/>
	</material>
	
	<material name="white">
		<color rgba="1 1 1 1"/>
	</material>
		
	<link name="base">
		<visual>
			<geometry>
				<cylinder length="1" radius="1"/>
			</geometry>
			<origin rpy="0 0 0" xyz="0 0 0.5"/>
			<collision>
				<geometry>
					<cylinder length="1" radius="1"/>
				</geometry>
				<origin rpy="0 0 0" xyz="0 0 0.5"/>
			</collision>
			<material name="red"/>
		</visual>
		
	</link>

	<link name="rotor">
		<visual>
			<geometry>
				<box size="5 2 0.5" />
			</geometry>
			<origin rpy="0 0 0" xyz="1.5 0 0.25"/>
			<collision>
				<geometry>
					<box size="5 2 0.5" />
				</geometry>
				<origin rpy="0 0 0" xyz="1.5 0 0.25"/>
			</collision>
			<material name="green"/>
		</visual>
	</link>  	
	<joint name="baseRotor" type="continuous">
		<parent link="base"/>
		<child link="rotor"/>
		<origin xyz="0 0 1"/>
	</joint>
<!--
	<joint name="elbow2" type="continuous">
		<parent link="link1"/>
		<child link="rotor"/>
		<origin xyz="0 0 4"/>
		<axis xyz="0 0 1"/>
	</joint>
	
	
	
	<joint name="carpus" type="prismatic">
		<parent link="forarm"/>
		<child link="wrist"/>
		<origin xyz="0 1 0"/>
	</joint>
	
	<joint name="phalanx" type="prismatic">
		<parent link="wrist"/>
		<child link="finger"/>
		<origin xyz="1 0 0"/>
	</joint>
	
	<link name="wrist">
		<visual>
			<geometry>
				<box size="10 1 1" />
			</geometry>
			<origin rpy="0 0 0" xyz="0 0 0"/>
			<material name="green"/>
		</visual>
	</link>
	
	<link name="finger">
		<visual>
			<geometry>
				<box size="0.2 0.2 0.5" />
			</geometry>
			<origin rpy="0 0 0" xyz="0 0 0"/>
			<material name="white"/>
		</visual>
	</link>
-->

</robot>
